Operations to perform:
  Apply all migrations: admin, auth, contenttypes, sessions, website
Running migrations:
  Applying contenttypes.0001_initial... OK
  Applying contenttypes.0002_remove_content_type_name... OK
  Applying auth.0001_initial... OK
  Applying auth.0002_alter_permission_name_max_length... OK
  Applying auth.0003_alter_user_email_max_length... OK
  Applying auth.0004_alter_user_username_opts... OK
  Applying auth.0005_alter_user_last_login_null... OK
  Applying auth.0006_require_contenttypes_0002... OK
  Applying auth.0007_alter_validators_add_error_messages... OK
  Applying auth.0008_alter_user_username_max_length... OK
  Applying auth.0009_alter_user_last_name_max_length... OK
  Applying auth.0010_alter_group_name_max_length... OK
  Applying auth.0011_update_proxy_permissions... OK
  Applying auth.0012_alter_user_first_name_max_length... OK
  Applying website.0001_initial... OK
  Applying admin.0001_initial... OK
  Applying admin.0002_logentry_remove_auto_add... OK
  Applying admin.0003_logentry_add_action_flag_choices... OK
  Applying sessions.0001_initial... OK
  Applying website.0002_auto_20240617_1407... OK
  Applying website.0003_game... OK
  Applying website.0004_game_gameover_tournament... OK
  Applying website.0005_game_winner_alter_tournament_idbc... OK
Traceback (most recent call last):
  File "/usr/local/lib/python3.11/site-packages/django/db/backends/utils.py", line 105, in _execute
    return self.cursor.execute(sql, params)
           ^^^^^^^^^^^^^^^^^^^^^^^^^^^^^^^^
  File "/usr/local/lib/python3.11/site-packages/psycopg/cursor.py", line 732, in execute
    raise ex.with_traceback(None)
psycopg.errors.NotNullViolation: null value in column "username" of relation "website_user" violates not-null constraint
DETAIL:  Failing row contains (1, !xhA2wNIhuLD5cwFQ63zAGRjvTGtj84QnibuGJ8uw, null, t, null, , , , t, t, 2024-07-20 11:12:01.133438+00, profilPicture/default.jpg, t).

The above exception was the direct cause of the following exception:

Traceback (most recent call last):
  File "/code/manage.py", line 22, in <module>
    main()
  File "/code/manage.py", line 18, in main
    execute_from_command_line(sys.argv)
  File "/usr/local/lib/python3.11/site-packages/django/core/management/__init__.py", line 442, in execute_from_command_line
    utility.execute()
  File "/usr/local/lib/python3.11/site-packages/django/core/management/__init__.py", line 436, in execute
    self.fetch_command(subcommand).run_from_argv(self.argv)
  File "/usr/local/lib/python3.11/site-packages/django/core/management/base.py", line 413, in run_from_argv
    self.execute(*args, **cmd_options)
  File "/usr/local/lib/python3.11/site-packages/django/core/management/base.py", line 459, in execute
    output = self.handle(*args, **options)
             ^^^^^^^^^^^^^^^^^^^^^^^^^^^^^
  File "/usr/local/lib/python3.11/site-packages/django/core/management/base.py", line 107, in wrapper
    res = handle_func(*args, **kwargs)
          ^^^^^^^^^^^^^^^^^^^^^^^^^^^^
  File "/usr/local/lib/python3.11/site-packages/django/core/management/commands/migrate.py", line 356, in handle
    post_migrate_state = executor.migrate(
                         ^^^^^^^^^^^^^^^^^
  File "/usr/local/lib/python3.11/site-packages/django/db/migrations/executor.py", line 135, in migrate
    state = self._migrate_all_forwards(
            ^^^^^^^^^^^^^^^^^^^^^^^^^^^
  File "/usr/local/lib/python3.11/site-packages/django/db/migrations/executor.py", line 167, in _migrate_all_forwards
    state = self.apply_migration(
            ^^^^^^^^^^^^^^^^^^^^^
  File "/usr/local/lib/python3.11/site-packages/django/db/migrations/executor.py", line 252, in apply_migration
    state = migration.apply(state, schema_editor)
            ^^^^^^^^^^^^^^^^^^^^^^^^^^^^^^^^^^^^^
  File "/usr/local/lib/python3.11/site-packages/django/db/migrations/migration.py", line 132, in apply
    operation.database_forwards(
  File "/usr/local/lib/python3.11/site-packages/django/db/migrations/operations/special.py", line 193, in database_forwards
    self.code(from_state.apps, schema_editor)
  File "/code/website/migrations/0006_auto_20240715_1448.py", line 18, in create_superuser
    user.save()
  File "/usr/local/lib/python3.11/site-packages/django/db/models/base.py", line 822, in save
    self.save_base(
  File "/usr/local/lib/python3.11/site-packages/django/db/models/base.py", line 909, in save_base
    updated = self._save_table(
              ^^^^^^^^^^^^^^^^^
  File "/usr/local/lib/python3.11/site-packages/django/db/models/base.py", line 1071, in _save_table
    results = self._do_insert(
              ^^^^^^^^^^^^^^^^
  File "/usr/local/lib/python3.11/site-packages/django/db/models/base.py", line 1112, in _do_insert
    return manager._insert(
           ^^^^^^^^^^^^^^^^
  File "/usr/local/lib/python3.11/site-packages/django/db/models/manager.py", line 87, in manager_method
    return getattr(self.get_queryset(), name)(*args, **kwargs)
           ^^^^^^^^^^^^^^^^^^^^^^^^^^^^^^^^^^^^^^^^^^^^^^^^^^^
  File "/usr/local/lib/python3.11/site-packages/django/db/models/query.py", line 1847, in _insert
    return query.get_compiler(using=using).execute_sql(returning_fields)
           ^^^^^^^^^^^^^^^^^^^^^^^^^^^^^^^^^^^^^^^^^^^^^^^^^^^^^^^^^^^^^
  File "/usr/local/lib/python3.11/site-packages/django/db/models/sql/compiler.py", line 1823, in execute_sql
    cursor.execute(sql, params)
  File "/usr/local/lib/python3.11/site-packages/django/db/backends/utils.py", line 122, in execute
    return super().execute(sql, params)
           ^^^^^^^^^^^^^^^^^^^^^^^^^^^^
  File "/usr/local/lib/python3.11/site-packages/django/db/backends/utils.py", line 79, in execute
    return self._execute_with_wrappers(
           ^^^^^^^^^^^^^^^^^^^^^^^^^^^^
  File "/usr/local/lib/python3.11/site-packages/django/db/backends/utils.py", line 92, in _execute_with_wrappers
    return executor(sql, params, many, context)
           ^^^^^^^^^^^^^^^^^^^^^^^^^^^^^^^^^^^^
  File "/usr/local/lib/python3.11/site-packages/django/db/backends/utils.py", line 100, in _execute
    with self.db.wrap_database_errors:
  File "/usr/local/lib/python3.11/site-packages/django/db/utils.py", line 91, in __exit__
    raise dj_exc_value.with_traceback(traceback) from exc_value
  File "/usr/local/lib/python3.11/site-packages/django/db/backends/utils.py", line 105, in _execute
    return self.cursor.execute(sql, params)
           ^^^^^^^^^^^^^^^^^^^^^^^^^^^^^^^^
  File "/usr/local/lib/python3.11/site-packages/psycopg/cursor.py", line 732, in execute
    raise ex.with_traceback(None)
django.db.utils.IntegrityError: null value in column "username" of relation "website_user" violates not-null constraint
DETAIL:  Failing row contains (1, !xhA2wNIhuLD5cwFQ63zAGRjvTGtj84QnibuGJ8uw, null, t, null, , , , t, t, 2024-07-20 11:12:01.133438+00, profilPicture/default.jpg, t).
  Applying website.0006_auto_20240715_1448...Performing system checks...

System check identified no issues (0 silenced).

You have 4 unapplied migration(s). Your project may not work properly until you apply the migrations for app(s): website.
Run 'python manage.py migrate' to apply them.
July 20, 2024 - 13:12:03
Django version 5.0.7, using settings 'transcendence.settings'
Starting ASGI/Channels version 3.0.5 development server at http://0.0.0.0:8000/
Quit the server with CONTROL-C.
